2022-12-15 13:55:27,022 INFO    StreamThr :21302 [internal.py:wandb_internal():88] W&B internal server running at pid: 21302, started at: 2022-12-15 13:55:27.020997
2022-12-15 13:55:27,112 DEBUG   HandlerThread:21302 [handler.py:handle_request():139] handle_request: status
2022-12-15 13:55:27,112 DEBUG   SenderThread:21302 [sender.py:send_request():317] send_request: status
2022-12-15 13:55:27,114 DEBUG   SenderThread:21302 [sender.py:send():303] send: header
2022-12-15 13:55:27,115 INFO    WriterThread:21302 [datastore.py:open_for_write():75] open: /media/breeze/dev/Mf_Cls/wandb/run-20221215_135526-363mmj99/run-363mmj99.wandb
2022-12-15 13:55:27,115 DEBUG   SenderThread:21302 [sender.py:send():303] send: run
2022-12-15 13:55:27,120 INFO    SenderThread:21302 [sender.py:_maybe_setup_resume():593] checking resume status for None/U-Net/363mmj99
2022-12-15 13:55:30,624 ERROR   SenderThread:21302 [retry.py:__call__():154] Retry attempt failed:
Traceback (most recent call last):
  File "/media/breeze/dev/Mf_Cls/venv/lib/python3.8/site-packages/urllib3/connection.py", line 174, in _new_conn
    conn = connection.create_connection(
  File "/media/breeze/dev/Mf_Cls/venv/lib/python3.8/site-packages/urllib3/util/connection.py", line 72, in create_connection
    for res in socket.getaddrinfo(host, port, family, socket.SOCK_STREAM):
  File "/usr/lib/python3.8/socket.py", line 918, in getaddrinfo
    for res in _socket.getaddrinfo(host, port, family, type, proto, flags):
socket.gaierror: [Errno -3] Temporary failure in name resolution

During handling of the above exception, another exception occurred:

Traceback (most recent call last):
  File "/media/breeze/dev/Mf_Cls/venv/lib/python3.8/site-packages/urllib3/connectionpool.py", line 703, in urlopen
    httplib_response = self._make_request(
  File "/media/breeze/dev/Mf_Cls/venv/lib/python3.8/site-packages/urllib3/connectionpool.py", line 386, in _make_request
    self._validate_conn(conn)
  File "/media/breeze/dev/Mf_Cls/venv/lib/python3.8/site-packages/urllib3/connectionpool.py", line 1042, in _validate_conn
    conn.connect()
  File "/media/breeze/dev/Mf_Cls/venv/lib/python3.8/site-packages/urllib3/connection.py", line 358, in connect
    self.sock = conn = self._new_conn()
  File "/media/breeze/dev/Mf_Cls/venv/lib/python3.8/site-packages/urllib3/connection.py", line 186, in _new_conn
    raise NewConnectionError(
urllib3.exceptions.NewConnectionError: <urllib3.connection.HTTPSConnection object at 0x7f44186d3880>: Failed to establish a new connection: [Errno -3] Temporary failure in name resolution

During handling of the above exception, another exception occurred:

Traceback (most recent call last):
  File "/media/breeze/dev/Mf_Cls/venv/lib/python3.8/site-packages/requests/adapters.py", line 489, in send
    resp = conn.urlopen(
  File "/media/breeze/dev/Mf_Cls/venv/lib/python3.8/site-packages/urllib3/connectionpool.py", line 787, in urlopen
    retries = retries.increment(
  File "/media/breeze/dev/Mf_Cls/venv/lib/python3.8/site-packages/urllib3/util/retry.py", line 592, in increment
    raise MaxRetryError(_pool, url, error or ResponseError(cause))
urllib3.exceptions.MaxRetryError: HTTPSConnectionPool(host='api.wandb.ai', port=443): Max retries exceeded with url: /graphql (Caused by NewConnectionError('<urllib3.connection.HTTPSConnection object at 0x7f44186d3880>: Failed to establish a new connection: [Errno -3] Temporary failure in name resolution'))

During handling of the above exception, another exception occurred:

Traceback (most recent call last):
  File "/media/breeze/dev/Mf_Cls/venv/lib/python3.8/site-packages/wandb/sdk/lib/retry.py", line 113, in __call__
    result = self._call_fn(*args, **kwargs)
  File "/media/breeze/dev/Mf_Cls/venv/lib/python3.8/site-packages/wandb/sdk/internal/internal_api.py", line 210, in execute
    return self.client.execute(*args, **kwargs)  # type: ignore
  File "/media/breeze/dev/Mf_Cls/venv/lib/python3.8/site-packages/wandb/vendor/gql-0.2.0/wandb_gql/client.py", line 52, in execute
    result = self._get_result(document, *args, **kwargs)
  File "/media/breeze/dev/Mf_Cls/venv/lib/python3.8/site-packages/wandb/vendor/gql-0.2.0/wandb_gql/client.py", line 60, in _get_result
    return self.transport.execute(document, *args, **kwargs)
  File "/media/breeze/dev/Mf_Cls/venv/lib/python3.8/site-packages/wandb/vendor/gql-0.2.0/wandb_gql/transport/requests.py", line 38, in execute
    request = requests.post(self.url, **post_args)
  File "/media/breeze/dev/Mf_Cls/venv/lib/python3.8/site-packages/requests/api.py", line 115, in post
    return request("post", url, data=data, json=json, **kwargs)
  File "/media/breeze/dev/Mf_Cls/venv/lib/python3.8/site-packages/requests/api.py", line 59, in request
    return session.request(method=method, url=url, **kwargs)
  File "/media/breeze/dev/Mf_Cls/venv/lib/python3.8/site-packages/requests/sessions.py", line 587, in request
    resp = self.send(prep, **send_kwargs)
  File "/media/breeze/dev/Mf_Cls/venv/lib/python3.8/site-packages/requests/sessions.py", line 701, in send
    r = adapter.send(request, **kwargs)
  File "/media/breeze/dev/Mf_Cls/venv/lib/python3.8/site-packages/requests/adapters.py", line 565, in send
    raise ConnectionError(e, request=request)
requests.exceptions.ConnectionError: HTTPSConnectionPool(host='api.wandb.ai', port=443): Max retries exceeded with url: /graphql (Caused by NewConnectionError('<urllib3.connection.HTTPSConnection object at 0x7f44186d3880>: Failed to establish a new connection: [Errno -3] Temporary failure in name resolution'))
2022-12-15 13:55:32,097 DEBUG   HandlerThread:21302 [handler.py:handle_request():139] handle_request: keepalive
2022-12-15 13:55:37,101 DEBUG   HandlerThread:21302 [handler.py:handle_request():139] handle_request: keepalive
2022-12-15 13:55:42,106 DEBUG   HandlerThread:21302 [handler.py:handle_request():139] handle_request: keepalive
